```python
import unittest
from django.core.exceptions import ValidationError
from django.db import models, transaction
from django.views import View
from django.shortcuts import render, get_object_or_404, HttpResponse
from uuid import uuid4

from Smodal.sale_items import SaleItem, ChatBot

class TestSaleItems(unittest.TestCase):

    def setUp(self):
        self.sale_item = SaleItem()
        self.chat_bot = ChatBot()

    def test_upload_item(self):
        item_data = {
            "item_id": uuid4(),
            "field1": "value1",
            "field2": "value2"
        }
        try:
            self.sale_item.upload_item(item_data)
        except Exception as e:
            self.fail("upload_item() raised Exception unexpectedly!")

    def test_upload_item_fail(self):
        item_data = "This should fail"
        with self.assertRaises(ValueError):
            self.sale_item.upload_item(item_data)

    def test_download_item(self):
        item_id = uuid4()
        item_data = {
            "item_id": item_id,
            "field1": "value1",
            "field2": "value2"
        }
        self.sale_item.upload_item(item_data)

        try:
            downloaded_item = self.sale_item.download_item(item_id)
            self.assertEqual(isinstance(downloaded_item, SaleItem), True)
        except Exception as e:
            self.fail("download_item() raised Exception unexpectedly!")

    def test_delete_item(self):
        item_id = uuid4()
        item_data = {
            "item_id": item_id,
            "field1": "value1",
            "field2": "value2"
        }
        self.sale_item.upload_item(item_data)

        try:
            self.sale_item.delete_item(item_id)
            with self.assertRaises(HttpResponse):
                self.sale_item.download_item(item_id)
        except Exception as e:
            self.fail("delete_item() raised Exception unexpectedly!")

    def test_viewing_window(self):
        try:
            chat = self.chat_bot.viewing_window()
            self.assertIsInstance(chat, str)
        except Exception as e:
            self.fail("viewing_window() raised Exception unexpectedly!")

    def test_engage_clients(self):
        message = "Hello, this is a test message."

        try:
            self.chat_bot.engage_clients(message)
            chat = self.chat_bot.viewing_window()

            self.assertEqual(chat, message)
        except Exception as e:
            self.fail("engage_clients() raised Exception unexpectedly!")

        with self.assertRaises(ValueError):
            self.chat_bot.engage_clients(12345)

    def test_take_over(self):
        new_chat_bot = ChatBot()

        new_chat_bot.chat = "Taken over"
        try:
            self.chat_bot.take_over(new_chat_bot)
            chat = self.chat_bot.viewing_window()

            self.assertEqual(chat, "Taken over")
        except Exception as e:
            self.fail("take_over() raised Exception unexpectedly!")

        with self.assertRaises(ValueError):
            self.chat_bot.take_over("This should fail")

if __name__ == '__main__':
    unittest.main()
```
